<!--
SPDX-FileCopyrightText: 2025 Humanoid Sensing and Perception, Istituto Italiano di Tecnologia
SPDX-License-Identifier: BSD-3-Clause
Code adapted from https://github.com/AndrejOrsula/shadow_hand_ign
-->
<robot xmlns:xacro="http://www.ros.org/wiki/xacro" name="shadow_hand_right">
    <xacro:macro name="shadow_model" params="mimic">
        <xacro:property name="yaml_file" value="../../adf/calib_eef.yaml" />
        <xacro:property name="calib_eef" value="${load_yaml(yaml_file)['shadow_hand_right']}"/>
        <!--  palm frame  -->
        <link name="eef_link">
            <inertial>
                <origin rpy="0 0 0" xyz="0 0 0"/>
                <mass value="0.0001"/>
                <inertia ixx="1e-5" ixy="0" ixz="0" iyy="1e-5" iyz="0" izz="1e-5"/>
            </inertial>
        </link>
        <joint name="r_eef_calib_joint" type="fixed">
            <parent link="eef_link"/>
            <child link="eef_calib_link"/>
            <origin xyz="${calib_eef['tx']} ${calib_eef['ty']} ${calib_eef['tz']}" 
                    rpy="${calib_eef['rx']} ${calib_eef['ry']} ${calib_eef['rz']}"/>
        </joint>
        <link name="eef_calib_link">
            <inertial>
                <origin rpy="0 0 0" xyz="0 0 0"/>
                <mass value="0.0001"/>
                <inertia ixx="1e-5" ixy="0" ixz="0" iyy="1e-5" iyz="0" izz="1e-5"/>
            </inertial>
        </link>
        <joint name="r_eef_fixed_joint" type="fixed">
            <parent link="eef_calib_link"/>
            <child link="palm_base_link"/>
            <origin xyz="-0.054 0.038 0.0" rpy="1.5708 -1.5708 0.7854"/>
        </joint>
        <link name="palm_base_link">
            <inertial>
                <origin rpy="0 0 0" xyz="0 0 0.035"/>
                <mass value="0.3"/>
                <inertia ixx="0.0003581" ixy="0.0" ixz="0.0" iyy="0.0005287" iyz="0.0" izz="0.000191"/>
            </inertial>
            <visual>
                <geometry>
                    <mesh filename="mesh/palm.obj"/>
                </geometry>
            </visual>
            <collision>
                <geometry>
                    <mesh filename="mesh/palm.stl"/>
                </geometry>
            </collision>
        </link>
        <joint name="r_forearm_fixed_joint" type="fixed">
            <parent link="palm_base_link"/>
            <child link="r_forearm"/>
            <origin xyz="0 0 0" rpy="0 -1.5708 0"/>
        </joint>
		<link name="r_forearm"/>
        
        <!--  thumb finger  -->
        <link name="r_thumb0">
            <inertial>
                <origin rpy="0 0 0" xyz="0 0 0"/>
                <mass value="0.0001"/>
                <inertia ixx="1e-5" ixy="0" ixz="0" iyy="1e-5" iyz="0" izz="1e-5"/>
            </inertial>
            <visual>
                <geometry>
                    <box size="0.001 0.001 0.001"/>
                </geometry>
            </visual>
            <collision>
                <geometry>
                    <sphere radius="0.011"/>
                </geometry>
            </collision>
        </link>
        <joint name="r_00thumb0" type="revolute">
            <parent link="palm_base_link"/>
            <child link="r_thumb0"/>
            <origin rpy="-0.7853981633974483 0 -1.5707963267948966" xyz="0.034 -0.00858 0.029"/>
            <axis xyz="0 0 -1"/>
            <limit effort="5.0" lower="-1.0471975511965976" upper="1.0471975511965976" velocity="4.0"/>
        </joint>
        <link name="r_thumb1">
            <inertial>
                <mass value="0.040"/>
                <origin rpy="0 0 0" xyz="0 0 0.019"/>
                <inertia ixx="0.0000136" ixy="0.0" ixz="0.0" iyy="0.0000136" iyz="0.0" izz="0.00000313"/>
            </inertial>
            <visual>
                <geometry>
                    <mesh filename="mesh/th_proximal.obj"/>
                </geometry>
            </visual>
            <collision>
                <geometry>
                    <mesh filename="mesh/th_proximal.stl"/>
                </geometry>
            </collision>
        </link>
        <joint name="r_01thumb1" type="revolute">
            <parent link="r_thumb0"/>
            <child link="r_thumb1"/>
            <origin rpy="0 0 0" xyz="0 0 0"/>
            <axis xyz="0 1 0"/>
            <limit effort="3" lower="0.0" upper="1.2217304763960306" velocity="4.0"/>
        </joint>
        <link name="r_thumb2">
            <inertial>
                <origin rpy="0 0 0" xyz="0 0 0"/>
                <mass value="0.0001"/>
                <inertia ixx="1e-5" ixy="0" ixz="0" iyy="1e-5" iyz="0" izz="1e-5"/>
            </inertial>
            <visual>
                <geometry>
                    <box size="0.001 0.001 0.001"/>
                </geometry>
            </visual>
            <collision>
                <geometry>
                    <sphere radius="0.010"/>
                </geometry>
            </collision>
        </link>
        <joint name="r_02thumb2" type="revolute">
            <parent link="r_thumb1"/>
            <child link="r_thumb2"/>
            <origin rpy="0 0 0" xyz="0 0 0.038"/>
            <axis xyz="0 1 0"/>
            <limit effort="2.0" lower="-0.20943951023931953" upper="0.20943951023931953" velocity="4.0"/>
        </joint>
        <link name="r_thumb3">
            <inertial>
                <mass value="0.020"/>
                <origin rpy="0 0 0" xyz="0 0 0.016"/>
                <inertia ixx="0.0000051" ixy="0.0" ixz="0.0" iyy="0.0000051" iyz="0.0" izz="0.00000121"/>
            </inertial>
            <visual>
                <geometry>
                    <mesh filename="mesh/th_middle.obj"/>
                </geometry>
            </visual>
            <collision>
                <geometry>
                    <mesh filename="mesh/th_middle.stl"/>
                </geometry>
            </collision>
        </link>
        <joint name="r_03thumb3" type="revolute">
            <parent link="r_thumb2"/>
            <child link="r_thumb3"/>
            <origin rpy="0 0 0" xyz="0 0 0"/>
            <axis xyz="1 0 0"/>
            <limit effort="2.0" lower="-0.6981317007977318" upper="0.6981317007977318" velocity="2.0"/>
        </joint>
        <link name="r_thumb4">
            <inertial>
                <mass value="0.016"/>
                <origin rpy="0 0 0" xyz="0 0 0.01375"/>
                <inertia ixx="0.0000021" ixy="0.0" ixz="0.0" iyy="0.0000022" iyz="0.0" izz="0.000001"/>
            </inertial>
            <visual>
                <geometry>
                    <mesh filename="mesh/th_distal.obj"/>
                </geometry>
            </visual>
            <collision>
                <geometry>
                    <mesh filename="mesh/th_distal.stl"/>
                </geometry>
            </collision>
        </link>
        <joint name="r_04thumb4" type="revolute">
            <parent link="r_thumb3"/>
            <child link="r_thumb4"/>
            <origin rpy="0 0 0" xyz="0 0 0.032"/>
            <axis xyz="1 0 0"/>
            <limit effort="1.0" lower="-0.2617993877991494" upper="1.5707963267948966" velocity="4.0"/>
        </joint>

        <!--  index finger  -->
        <link name="r_index0">
            <inertial>
                <origin rpy="0 0 0" xyz="0 0 0"/>
                <mass value="0.008"/>
                <inertia ixx="0.00000026" ixy="0.0" ixz="0.0" iyy="0.00000026" iyz="0.0" izz="0.00000032"/>
            </inertial>
            <visual>
                <geometry>
                    <mesh filename="mesh/f_knuckle.obj"/>
                </geometry>
            </visual>
            <collision>
                <geometry>
                    <mesh filename="mesh/f_knuckle.stl"/>
                </geometry>
            </collision>
        </link>
        <joint name="r_05index0" type="revolute">
            <parent link="palm_base_link"/>
            <child link="r_index0"/>
            <origin rpy="0 0 0" xyz="0.033 0 0.095"/>
            <axis xyz="0 -1 0"/>
            <limit effort="2" lower="-0.3490658503988659" upper="0.3490658503988659" velocity="2.0"/>
        </joint>
        <link name="r_index1">
            <inertial>
                <mass value="0.030"/>
                <origin xyz="0 0 0.0225"/>
                <inertia ixx="0.0000098" ixy="0.0" ixz="0.0" iyy="0.00001" iyz="0.0" izz="0.0000018"/>
            </inertial>
            <visual>
                <geometry>
                    <mesh filename="mesh/f_proximal.obj"/>
                </geometry>
            </visual>
            <collision>
                <geometry>
                    <mesh filename="mesh/f_proximal.stl"/>
                </geometry>
            </collision>
        </link>
        <joint name="r_06index1" type="revolute">
            <parent link="r_index0"/>
            <child link="r_index1"/>
            <origin rpy="0 0 0" xyz="0 0 0"/>
            <axis xyz="1 0 0"/>
            <limit effort="2" lower="-0.2617993877991494" upper="1.5707963267948966" velocity="2.0"/>
        </joint>
        <link name="r_index2">
            <inertial>
                <origin rpy="0 0 0" xyz="0 0 0.0125"/>
                <mass value="0.017"/>
                <inertia ixx="0.0000026" ixy="0.0" ixz="0.0" iyy="0.0000027" iyz="0.0" izz="0.00000087"/>
            </inertial>
            <visual>
                <geometry>
                    <mesh filename="mesh/f_middle.obj"/>
                </geometry>
            </visual>
            <collision>
                <geometry>
                    <mesh filename="mesh/f_middle.stl"/>
                </geometry>
            </collision>
        </link>
        <joint name="r_070index2" type="revolute">
            <parent link="r_index1"/>
            <child link="r_index2"/>
            <origin rpy="0 0 0" xyz="0 0 0.045"/>
            <axis xyz="1 0 0"/>
            <limit effort="2" lower="0" upper="1.5707963267948966" velocity="2.0"/>
        </joint>
        <link name="r_index3">
            <inertial>
                <mass value="0.012"/>
                <origin xyz="0 0 0.012"/>
                <inertia ixx="0.00000094" ixy="0.0" ixz="0.0" iyy="0.0000011" iyz="0.0" izz="0.00000053"/>
            </inertial>
            <visual>
                <geometry>
                    <mesh filename="mesh/f_distal.obj"/>
                </geometry>
            </visual>
            <collision>
                <geometry>
                    <mesh filename="mesh/f_distal.stl"/>
                </geometry>
            </collision>
        </link>
        <joint name="r_071index3" type="revolute">
            <parent link="r_index2"/>
            <child link="r_index3"/>
            <origin rpy="0 0 0" xyz="0 0 0.025"/>
            <axis xyz="1 0 0"/>
            <limit effort="2" lower="0" upper="1.5707963267948966" velocity="2.0"/>
            <xacro:if value="${mimic}">
                <mimic joint="r_070index2" multiplier="1" offset="0"/>
            </xacro:if>
        </joint>

        <!--  middle finger  -->
        <link name="r_middle0">
            <inertial>
                <origin rpy="0 0 0" xyz="0 0 0"/>
                <mass value="0.008"/>
                <inertia ixx="0.00000026" ixy="0.0" ixz="0.0" iyy="0.00000026" iyz="0.0" izz="0.00000032"/>
            </inertial>
            <visual>
                <geometry>
                    <mesh filename="mesh/f_knuckle.obj"/>
                </geometry>
            </visual>
            <collision>
                <geometry>
                    <mesh filename="mesh/f_knuckle.stl"/>
                </geometry>
            </collision>
        </link>
        <joint name="r_08middle0" type="revolute">
            <parent link="palm_base_link"/>
            <child link="r_middle0"/>
            <origin rpy="0 0 0" xyz="0.011 0 0.099"/>
            <axis xyz="0 -1 0"/>
            <limit effort="2" lower="-0.3490658503988659" upper="0.3490658503988659" velocity="2.0"/>
        </joint>
        <link name="r_middle1">
            <inertial>
                <mass value="0.030"/>
                <origin xyz="0 0 0.0225"/>
                <inertia ixx="0.0000098" ixy="0.0" ixz="0.0" iyy="0.00001" iyz="0.0" izz="0.0000018"/>
            </inertial>
            <visual>
                <geometry>
                    <mesh filename="mesh/f_proximal.obj"/>
                </geometry>
            </visual>
            <collision>
                <geometry>
                    <mesh filename="mesh/f_proximal.stl"/>
                </geometry>
            </collision>
        </link>
        <joint name="r_09middle1" type="revolute">
            <parent link="r_middle0"/>
            <child link="r_middle1"/>
            <origin rpy="0 0 0" xyz="0 0 0"/>
            <axis xyz="1 0 0"/>
            <limit effort="2" lower="-0.2617993877991494" upper="1.5707963267948966" velocity="2.0"/>
        </joint>
        <link name="r_middle2">
            <inertial>
                <origin rpy="0 0 0" xyz="0 0 0.0125"/>
                <mass value="0.017"/>
                <inertia ixx="0.0000026" ixy="0.0" ixz="0.0" iyy="0.0000027" iyz="0.0" izz="0.00000087"/>
            </inertial>
            <visual>
                <geometry>
                    <mesh filename="mesh/f_middle.obj"/>
                </geometry>
            </visual>
            <collision>
                <geometry>
                    <mesh filename="mesh/f_middle.stl"/>
                </geometry>
            </collision>
        </link>
        <joint name="r_100middle2" type="revolute">
            <parent link="r_middle1"/>
            <child link="r_middle2"/>
            <origin rpy="0 0 0" xyz="0 0 0.045"/>
            <axis xyz="1 0 0"/>
            <limit effort="2" lower="0" upper="1.5707963267948966" velocity="2.0"/>
        </joint>
        <link name="r_middle3">
            <inertial>
                <mass value="0.012"/>
                <origin xyz="0 0 0.012"/>
                <inertia ixx="0.00000094" ixy="0.0" ixz="0.0" iyy="0.0000011" iyz="0.0" izz="0.00000053"/>
            </inertial>
            <visual>
                <geometry>
                    <mesh filename="mesh/f_distal.obj"/>
                </geometry>
            </visual>
            <collision>
                <geometry>
                    <mesh filename="mesh/f_distal.stl"/>
                </geometry>
            </collision>
        </link>
        <joint name="r_101middle3" type="revolute">
            <parent link="r_middle2"/>
            <child link="r_middle3"/>
            <origin rpy="0 0 0" xyz="0 0 0.025"/>
            <axis xyz="1 0 0"/>
            <limit effort="2" lower="0" upper="1.5707963267948966" velocity="2.0"/>
            <xacro:if value="${mimic}">
                <mimic joint="r_100middle2" multiplier="1" offset="0"/>
            </xacro:if>
        </joint>

        <!--  ring finger  -->
        <link name="r_ring0">
            <inertial>
                <origin rpy="0 0 0" xyz="0 0 0"/>
                <mass value="0.008"/>
                <inertia ixx="0.00000026" ixy="0.0" ixz="0.0" iyy="0.00000026" iyz="0.0" izz="0.00000032"/>
            </inertial>
            <visual>
                <geometry>
                    <mesh filename="mesh/f_knuckle.obj"/>
                </geometry>
            </visual>
            <collision>
                <geometry>
                    <mesh filename="mesh/f_knuckle.stl"/>
                </geometry>
            </collision>
        </link>
        <joint name="r_11ring0" type="revolute">
            <parent link="palm_base_link"/>
            <child link="r_ring0"/>
            <origin rpy="0 0 0" xyz="-0.011 0 0.095"/>
            <axis xyz="0 1 0"/>
            <limit effort="2" lower="-0.3490658503988659" upper="0.3490658503988659" velocity="2.0"/>
        </joint>
        <link name="r_ring1">
            <inertial>
                <mass value="0.030"/>
                <origin xyz="0 0 0.0225"/>
                <inertia ixx="0.0000098" ixy="0.0" ixz="0.0" iyy="0.00001" iyz="0.0" izz="0.0000018"/>
            </inertial>
            <visual>
                <geometry>
                    <mesh filename="mesh/f_proximal.obj"/>
                </geometry>
            </visual>
            <collision>
                <geometry>
                    <mesh filename="mesh/f_proximal.stl"/>
                </geometry>
            </collision>
        </link>
        <joint name="r_12ring1" type="revolute">
            <parent link="r_ring0"/>
            <child link="r_ring1"/>
            <origin rpy="0 0 0" xyz="0 0 0"/>
            <axis xyz="1 0 0"/>
            <limit effort="2" lower="-0.2617993877991494" upper="1.5707963267948966" velocity="2.0"/>
        </joint>
        <link name="r_ring2">
            <inertial>
                <origin rpy="0 0 0" xyz="0 0 0.0125"/>
                <mass value="0.017"/>
                <inertia ixx="0.0000026" ixy="0.0" ixz="0.0" iyy="0.0000027" iyz="0.0" izz="0.00000087"/>
            </inertial>
            <visual>
                <geometry>
                    <mesh filename="mesh/f_middle.obj"/>
                </geometry>
            </visual>
            <collision>
                <geometry>
                    <mesh filename="mesh/f_middle.stl"/>
                </geometry>
            </collision>
        </link>
        <joint name="r_130ring2" type="revolute">
            <parent link="r_ring1"/>
            <child link="r_ring2"/>
            <origin rpy="0 0 0" xyz="0 0 0.045"/>
            <axis xyz="1 0 0"/>
            <limit effort="2" lower="0" upper="1.5707963267948966" velocity="2.0"/>
        </joint>
        <link name="r_ring3">
            <inertial>
                <mass value="0.012"/>
                <origin xyz="0 0 0.012"/>
                <inertia ixx="0.00000094" ixy="0.0" ixz="0.0" iyy="0.0000011" iyz="0.0" izz="0.00000053"/>
            </inertial>
            <visual>
                <geometry>
                    <mesh filename="mesh/f_distal.obj"/>
                </geometry>
            </visual>
            <collision>
                <geometry>
                    <mesh filename="mesh/f_distal.stl"/>
                </geometry>
            </collision>
        </link>
        <joint name="r_131ring3" type="revolute">
            <parent link="r_ring2"/>
            <child link="r_ring3"/>
            <origin rpy="0 0 0" xyz="0 0 0.025"/>
            <axis xyz="1 0 0"/>
            <limit effort="2" lower="0" upper="1.5707963267948966" velocity="2.0"/>
            <xacro:if value="${mimic}">
                <mimic joint="r_130ring2" multiplier="1" offset="0"/>
            </xacro:if>
        </joint>

        <!--  pinkie finger  -->
        <link name="r_pinkie00">
            <inertial>
                <origin rpy="0 0.9599 0" xyz="0.03174867647058824 0 0.02235294117647059"/>
                <mass value="0.030"/>
                <inertia ixx="0.0000145" ixy="0.0" ixz="0.0" iyy="0.00001638" iyz="0.0" izz="0.000004272"/>
            </inertial>
            <visual>
                <geometry>
                    <mesh filename="mesh/lf_metacarpal.obj"/>
                </geometry>
            </visual>
            <collision>
                <geometry>
                    <mesh filename="mesh/lf_metacarpal.stl"/>
                </geometry>
            </collision>
        </link>
        <joint name="r_14pinkie00" type="revolute">
            <parent link="palm_base_link"/>
            <child link="r_pinkie00"/>
            <origin rpy="0 -0.9599 0" xyz="-0.033 0 0.02071"/>
            <axis xyz="1 0 0"/>
            <limit effort="2" lower="0" upper="0.7853981633974483" velocity="2.0"/>
        </joint>
        <link name="r_pinkie0">
            <inertial>
                <origin rpy="0 0 0" xyz="0 0 0"/>
                <mass value="0.008"/>
                <inertia ixx="0.00000026" ixy="0.0" ixz="0.0" iyy="0.00000026" iyz="0.0" izz="0.00000032"/>
            </inertial>
            <visual>
                <geometry>
                    <mesh filename="mesh/f_knuckle.obj"/>
                </geometry>
            </visual>
            <collision>
                <geometry>
                    <mesh filename="mesh/f_knuckle.stl"/>
                </geometry>
            </collision>
        </link>
        <joint name="r_15pinkie0" type="revolute">
            <parent link="r_pinkie00"/>
            <child link="r_pinkie0"/>
            <origin rpy="0 0.9599 0" xyz="0.05397275 0 0.03779463"/>
            <axis xyz="0 1 0"/>
            <limit effort="2" lower="-0.3490658503988659" upper="0.3490658503988659" velocity="2.0"/>
        </joint>
        <link name="r_pinkie1">
            <inertial>
                <mass value="0.030"/>
                <origin xyz="0 0 0.0225"/>
                <inertia ixx="0.0000098" ixy="0.0" ixz="0.0" iyy="0.00001" iyz="0.0" izz="0.0000018"/>
            </inertial>
            <visual>
                <geometry>
                    <mesh filename="mesh/f_proximal.obj"/>
                </geometry>
            </visual>
            <collision>
                <geometry>
                    <mesh filename="mesh/f_proximal.stl"/>
                </geometry>
            </collision>
        </link>
        <joint name="r_16pinkie1" type="revolute">
            <parent link="r_pinkie0"/>
            <child link="r_pinkie1"/>
            <origin rpy="0 0 0" xyz="0 0 0"/>
            <axis xyz="1 0 0"/>
            <limit effort="2" lower="-0.2617993877991494" upper="1.5707963267948966" velocity="2.0"/>
        </joint>
        <link name="r_pinkie2">
            <inertial>
                <origin rpy="0 0 0" xyz="0 0 0.0125"/>
                <mass value="0.017"/>
                <inertia ixx="0.0000026" ixy="0.0" ixz="0.0" iyy="0.0000027" iyz="0.0" izz="0.00000087"/>
            </inertial>
            <visual>
                <geometry>
                    <mesh filename="mesh/f_middle.obj"/>
                </geometry>
            </visual>
            <collision>
                <geometry>
                    <mesh filename="mesh/f_middle.stl"/>
                </geometry>
            </collision>
        </link>
        <joint name="r_170pinkie2" type="revolute">
            <parent link="r_pinkie1"/>
            <child link="r_pinkie2"/>
            <origin rpy="0 0 0" xyz="0 0 0.045"/>
            <axis xyz="1 0 0"/>
            <limit effort="2" lower="0" upper="1.5707963267948966" velocity="2.0"/>
        </joint>
        <link name="r_pinkie3">
            <inertial>
                <mass value="0.012"/>
                <origin xyz="0 0 0.012"/>
                <inertia ixx="0.00000094" ixy="0.0" ixz="0.0" iyy="0.0000011" iyz="0.0" izz="0.00000053"/>
            </inertial>
            <visual>
                <geometry>
                    <mesh filename="mesh/f_distal.obj"/>
                </geometry>
            </visual>
            <collision>
                <geometry>
                    <mesh filename="mesh/f_distal.stl"/>
                </geometry>
            </collision>
        </link>
        <joint name="r_171pinkie3" type="revolute">
            <parent link="r_pinkie2"/>
            <child link="r_pinkie3"/>
            <origin rpy="0 0 0" xyz="0 0 0.025"/>
            <axis xyz="1 0 0"/>
            <limit effort="2" lower="0" upper="1.5707963267948966" velocity="2.0"/>
            <xacro:if value="${mimic}">
                <mimic joint="r_170pinkie2" multiplier="1" offset="0"/>
            </xacro:if>
        </joint>
    </xacro:macro>

    <xacro:macro name="shadow_anchor">
        <!--  anchor  -->
        <link name="A_00"/>
        <link name="A_01"/>
        <link name="A_02"/>
        <link name="A_03"/>
        <link name="A_04"/>
        <link name="A_05"/>
        <link name="A_06"/>
        <link name="A_07"/>
        <link name="A_08"/>
        <link name="A_09"/>
        <link name="A_10"/>
        <link name="A_11"/>
        <link name="A_12"/>
        <link name="A_13"/>
        <link name="A_14"/>
        <link name="A_15"/>
        <link name="A_16"/>
        <link name="A_17"/>
        <link name="A_18"/>
        <link name="A_19"/>
        <link name="A_20"/>
        <link name="A_21"/>
        <!--  thumb  -->
        <joint name="joint_A_00" type="fixed">
            <child link="A_00"/>
            <parent link="r_thumb1"/>
            <origin xyz="0 -0.011 0.02" rpy="0 0 0"/>
        </joint>
        <joint name="joint_A_01" type="fixed">
            <child link="A_01"/>
            <parent link="r_thumb3"/>
            <origin xyz="0 -0.01 0.016" rpy="0 0 0"/>
        </joint>
        <joint name="joint_A_02" type="fixed">
            <child link="A_02"/>
            <parent link="r_thumb4"/>
            <origin xyz="0 -0.009 0.02" rpy="0 0 0"/>
        </joint>
        <joint name="joint_A_03" type="fixed">
            <child link="A_03"/>
            <parent link="r_thumb4"/>
            <origin xyz="0 0 0.035" rpy="0 0 0"/>
        </joint>
        <!--  index  -->
        <joint name="joint_A_04" type="fixed">
            <child link="A_04"/>
            <parent link="r_index1"/>
            <origin xyz="0 -0.01 0.022" rpy="0 0 0"/>
        </joint>
        <joint name="joint_A_05" type="fixed">
            <child link="A_05"/>
            <parent link="r_index2"/>
            <origin xyz="0 -0.009 0.0125" rpy="0 0 0"/>
        </joint>
        <joint name="joint_A_06" type="fixed">
            <child link="A_06"/>
            <parent link="r_index3"/>
            <origin xyz="0 -0.0066 0.017" rpy="0 0 0"/>
        </joint>
        <joint name="joint_A_07" type="fixed">
            <child link="A_07"/>
            <parent link="r_index3"/>
            <origin xyz="0 0 0.03" rpy="0 0 0"/>
        </joint>
        <!--  mid  -->
        <joint name="joint_A_08" type="fixed">
            <child link="A_08"/>
            <parent link="r_middle1"/>
            <origin xyz="0 -0.01 0.022" rpy="0 0 0"/>
        </joint>
        <joint name="joint_A_09" type="fixed">
            <child link="A_09"/>
            <parent link="r_middle2"/>
            <origin xyz="0 -0.009 0.0125" rpy="0 0 0"/>
        </joint>
        <joint name="joint_A_10" type="fixed">
            <child link="A_10"/>
            <parent link="r_middle3"/>
            <origin xyz="0 -0.0066 0.017" rpy="0 0 0"/>
        </joint>
        <joint name="joint_A_11" type="fixed">
            <child link="A_11"/>
            <parent link="r_middle3"/>
            <origin xyz="0 0 0.03" rpy="0 0 0"/>
        </joint>
        <!--  ring  -->
        <joint name="joint_A_12" type="fixed">
            <child link="A_12"/>
            <parent link="r_ring1"/>
            <origin xyz="0 -0.01 0.022" rpy="0 0 0"/>
        </joint>
        <joint name="joint_A_13" type="fixed">
            <child link="A_13"/>
            <parent link="r_ring2"/>
            <origin xyz="0 -0.009 0.0125" rpy="0 0 0"/>
        </joint>
        <joint name="joint_A_14" type="fixed">
            <child link="A_14"/>
            <parent link="r_ring3"/>
            <origin xyz="0 -0.0066 0.017" rpy="0 0 0"/>
        </joint>
        <joint name="joint_A_15" type="fixed">
            <child link="A_15"/>
            <parent link="r_ring3"/>
            <origin xyz="0 0 0.03" rpy="0 0 0"/>
        </joint>
        <!--  pinkie  -->
        <joint name="joint_A_16" type="fixed">
            <child link="A_16"/>
            <parent link="r_pinkie1"/>
            <origin xyz="0 -0.01 0.022" rpy="0 0 0"/>
        </joint>
        <joint name="joint_A_17" type="fixed">
            <child link="A_17"/>
            <parent link="r_pinkie2"/>
            <origin xyz="0 -0.009 0.0125" rpy="0 0 0"/>
        </joint>
        <joint name="joint_A_18" type="fixed">
            <child link="A_18"/>
            <parent link="r_pinkie3"/>
            <origin xyz="0 -0.0066 0.017" rpy="0 0 0"/>
        </joint>
        <joint name="joint_A_19" type="fixed">
            <child link="A_19"/>
            <parent link="r_pinkie3"/>
            <origin xyz="0 0 0.03" rpy="0 0 0"/>
        </joint>
        <!--  palm  -->
        <joint name="joint_A_20" type="fixed">
            <child link="A_20"/>
            <parent link="palm_base_link"/>
            <origin xyz="0.033 -0.011 0.065" rpy="0 0 0"/>
        </joint>
        <joint name="joint_A_21" type="fixed">
            <child link="A_21"/>
            <parent link="palm_base_link"/>
            <origin xyz="-0.033 -0.011 0.061" rpy="0 0 0"/>
        </joint>
    </xacro:macro>
</robot>
