<!--
SPDX-FileCopyrightText: 2025 Humanoid Sensing and Perception, Istituto Italiano di Tecnologia
SPDX-License-Identifier: BSD-3-Clause
Code adapted from https://github.com/icub-tech-iit/ergocub-software under BSD-3-Clause license
-->
<robot xmlns:xacro="http://www.ros.org/wiki/xacro" name="ergocub_hand_right">
    <xacro:macro name="ergocub_model" params="mimic">
        <xacro:property name="yaml_file" value="../../adf/calib_eef.yaml" />
        <xacro:property name="calib_eef" value="${load_yaml(yaml_file)['ergocub_hand_right']}"/>
        <!--  palm frame  -->
        <link name="eef_link">
            <inertial>
                <origin rpy="0 0 0" xyz="0 0 0"/>
                <mass value="0.0001"/>
                <inertia ixx="1e-5" ixy="0" ixz="0" iyy="1e-5" iyz="0" izz="1e-5"/>
            </inertial>
        </link>
        <joint name="r_eef_calib_joint" type="fixed">
            <parent link="eef_link"/>
            <child link="eef_calib_link"/>
            <origin xyz="${calib_eef['tx']} ${calib_eef['ty']} ${calib_eef['tz']}" 
                    rpy="${calib_eef['rx']} ${calib_eef['ry']} ${calib_eef['rz']}"/>
        </joint>
        <link name="eef_calib_link">
            <inertial>
                <origin rpy="0 0 0" xyz="0 0 0"/>
                <mass value="0.0001"/>
                <inertia ixx="1e-5" ixy="0" ixz="0" iyy="1e-5" iyz="0" izz="1e-5"/>
            </inertial>
        </link>
        <joint name="r_eef_fixed_joint" type="fixed">
            <parent link="eef_calib_link"/>
            <child link="palm_base_link"/>
            <origin xyz="-0.059 0.035 0.0" rpy="-1.5708 -1.5708 0.8727"/>
        </joint>
        <link name="palm_base_link">
            <visual>
                <geometry>
                    <mesh filename="mesh/r_palm.stl"/>
                </geometry>
            </visual>
            <collision>
                <geometry>
                    <mesh filename="mesh/r_palm.obj"/>
                </geometry>
            </collision>
            <inertial>
                <origin rpy="0 0 0" xyz="0 0 0"/>
                <mass value="0.2"/>
                <inertia ixx="1e-3" ixy="0" ixz="0" iyy="1e-3" iyz="0" izz="1e-3"/>
            </inertial>
        </link>
        <joint name="r_forearm_fixed_joint" type="fixed">
            <parent link="palm_base_link"/>
            <child link="r_forearm"/>
            <origin xyz="0 0 0" rpy="0 1.5708 0"/>
        </joint>
		<link name="r_forearm"/>

        <!--  thumb  -->
        <joint name="r_00thumb1" type="revolute">
            <origin xyz="0.02337 0.003 -0.034524" rpy="0 -0.226892802651332 0"/>
            <axis xyz="0 0 1"/>
            <parent link="palm_base_link"/>
            <child link="r_thumb1"/>
            <limit lower="0" upper="1.7453292519943295" effort="4" velocity="4"/>
        </joint>
        <link name="r_thumb1">
            <visual>
                <geometry>
                    <mesh filename="mesh/r_thumb1.stl"/>
                </geometry>
            </visual>
            <inertial>
                <origin rpy="0 0 0" xyz="0 0 0"/>
                <mass value="0.05"/>
                <inertia ixx="1e-3" ixy="0" ixz="0" iyy="1e-3" iyz="0" izz="1e-3"/>
            </inertial>
        </link>
        <joint name="r_011thumb2" type="revolute">
            <origin xyz="0.0380746544995605 0.003469109580325286 -0.0036017448035497446" rpy="-1.7697290685198344 -0.13749152761469902 -2.965379613992927"/>
            <axis xyz="0 0 -1"/>
            <parent link="r_thumb1"/>
            <child link="r_thumb2"/>
            <limit lower="0" upper="1.5707963267948966" effort="4" velocity="4"/>
        </joint>
        <link name="r_thumb2">
            <visual>
                <geometry>
                    <mesh filename="mesh/r_thumb2.stl"/>
                </geometry>
            </visual>
            <collision>
                <geometry>
                    <mesh filename="mesh/r_thumb2.obj"/>
                </geometry>
            </collision>
            <inertial>
                <origin rpy="0 0 0" xyz="0 0 0"/>
                <mass value="0.05"/>
                <inertia ixx="1e-3" ixy="0" ixz="0" iyy="1e-3" iyz="0" izz="1e-3"/>
            </inertial>
        </link>
        <joint name="r_012thumb3" type="revolute">
            <origin xyz="-0.035 0.0015 0" rpy="0 0 3.1415926535883125"/>
            <axis xyz="0 0 -1"/>
            <parent link="r_thumb2"/>
            <child link="r_thumb3"/>
            <limit lower="0" upper="1.7697638615222502" effort="4" velocity="4"/>
            <xacro:if value="${mimic}">
                <mimic joint="r_011thumb2" multiplier="1" offset="0"/>
            </xacro:if>
        </joint>
        <link name="r_thumb3">
            <visual>
                <geometry>
                    <mesh filename="mesh/r_thumb3.stl"/>
                </geometry>
            </visual>
            <collision>
                <geometry>
                    <mesh filename="mesh/r_thumb3.obj"/>
                </geometry>
            </collision>
            <inertial>
                <origin rpy="0 0 0" xyz="0 0 0"/>
                <mass value="0.05"/>
                <inertia ixx="1e-3" ixy="0" ixz="0" iyy="1e-3" iyz="0" izz="1e-3"/>
            </inertial>
        </link>

        <!--  index  -->
        <joint name="r_02index1" type="revolute">
            <origin xyz="0.0225 0.0015 -0.0686" rpy="0 0.29670597283904 3.141592653589792"/>
            <axis xyz="0 -1 0"/>
            <parent link="palm_base_link"/>
            <child link="r_index1"/>
            <limit lower="0" upper="0.2617993877991494" effort="4" velocity="4"/>
        </joint>
        <link name="r_index1">
            <visual>
                <geometry>
                    <mesh filename="mesh/r_index1.stl"/>
                </geometry>
            </visual>
            <inertial>
                <origin rpy="0 0 0" xyz="0 0 0"/>
                <mass value="0.05"/>
                <inertia ixx="1e-3" ixy="0" ixz="0" iyy="1e-3" iyz="0" izz="1e-3"/>
            </inertial>
        </link>
        <joint name="r_031index2" type="revolute">
            <origin xyz="-0.00919 0 -0.030713451316238316" rpy="0 0 0"/>
            <axis xyz="-1 0 0"/>
            <parent link="r_index1"/>
            <child link="r_index2"/>
            <limit lower="0" upper="1.5707963267948966" effort="4" velocity="4"/>
        </joint>
        <link name="r_index2">
            <visual>
                <geometry>
                    <mesh filename="mesh/r_index2.stl"/>
                </geometry>
            </visual>
            <collision>
                <geometry>
                    <mesh filename="mesh/r_index2.obj"/>
                </geometry>
            </collision>
            <inertial>
                <origin rpy="0 0 0" xyz="0 0 0"/>
                <mass value="0.05"/>
                <inertia ixx="1e-3" ixy="0" ixz="0" iyy="1e-3" iyz="0" izz="1e-3"/>
            </inertial>
        </link>
        <joint name="r_032index3" type="revolute">
            <origin xyz="0 -0.0015 -0.04" rpy="0 0 0"/>
            <axis xyz="-1 0 0"/>
            <parent link="r_index2"/>
            <child link="r_index3"/>
            <limit lower="0" upper="1.7994344588061537" effort="4" velocity="4"/>
            <xacro:if value="${mimic}">
                <mimic joint="r_031index2" multiplier="1" offset="0"/>
            </xacro:if>
        </joint>
        <link name="r_index3">
            <visual>
                <geometry>
                    <mesh filename="mesh/r_index3.stl"/>
                </geometry>
            </visual>
            <collision>
                <geometry>
                    <mesh filename="mesh/r_index3.obj"/>
                </geometry>
            </collision>
            <inertial>
                <origin rpy="0 0 0" xyz="0 0 0"/>
                <mass value="0.05"/>
                <inertia ixx="1e-3" ixy="0" ixz="0" iyy="1e-3" iyz="0" izz="1e-3"/>
            </inertial>
        </link>

        <!--  middle  -->
        <joint name="r_041middle1" type="revolute">
            <origin xyz="0.0096 0.0015 -0.103" rpy="0 0 3.1415926535897927"/>
            <axis xyz="-1 0 0"/>
            <parent link="palm_base_link"/>
            <child link="r_middle1"/>
            <limit lower="0" upper="1.5707963267948966" effort="4" velocity="4"/>
        </joint>
        <link name="r_middle1">
            <visual>
                <geometry>
                    <mesh filename="mesh/r_middle1.stl"/>
                </geometry>
            </visual>
            <collision>
                <geometry>
                    <mesh filename="mesh/r_middle1.obj"/>
                </geometry>
            </collision>
            <inertial>
                <origin rpy="0 0 0" xyz="0 0 0"/>
                <mass value="0.05"/>
                <inertia ixx="1e-3" ixy="0" ixz="0" iyy="1e-3" iyz="0" izz="1e-3"/>
            </inertial>
        </link>
        <joint name="r_042middle2" type="revolute">
            <origin xyz="0 -0.0015 -0.04" rpy="0 0 0"/>
            <axis xyz="-1 0 0"/>
            <parent link="r_middle1"/>
            <child link="r_middle2"/>
            <limit lower="0" upper="1.7994344588061537" effort="4" velocity="4"/>
            <xacro:if value="${mimic}">
                <mimic joint="r_041middle1" multiplier="1" offset="0"/>
            </xacro:if>
        </joint>
        <link name="r_middle2">
            <visual>
                <geometry>
                    <mesh filename="mesh/r_middle2.stl"/>
                </geometry>
            </visual>
            <collision>
                <geometry>
                    <mesh filename="mesh/r_middle2.obj"/>
                </geometry>
            </collision>
            <inertial>
                <origin rpy="0 0 0" xyz="0 0 0"/>
                <mass value="0.05"/>
                <inertia ixx="1e-3" ixy="0" ixz="0" iyy="1e-3" iyz="0" izz="1e-3"/>
            </inertial>
        </link>

        <!--  ring  -->
        <joint name="r_051ring1" type="revolute">
            <origin xyz="-0.015417755568684424 0.001849813728471178 -0.09788067183717986" rpy="0 -0.08726646270762471 3.11541271480963"/>
            <axis xyz="-1 0 0"/>
            <parent link="palm_base_link"/>
            <child link="r_ring1"/>
            <limit lower="0" upper="1.5707963267948966" effort="4" velocity="4"/>
        </joint>
        <link name="r_ring1">
            <visual>
                <geometry>
                    <mesh filename="mesh/r_ring1.stl"/>
                </geometry>
            </visual>
            <collision>
                <geometry>
                    <mesh filename="mesh/r_ring1.obj"/>
                </geometry>
            </collision>
            <inertial>
                <origin rpy="0 0 0" xyz="0 0 0"/>
                <mass value="0.05"/>
                <inertia ixx="1e-3" ixy="0" ixz="0" iyy="1e-3" iyz="0" izz="1e-3"/>
            </inertial>
        </link>
        <joint name="r_052ring2" type="revolute">
            <origin xyz="0 -0.0015 -0.04" rpy="-0 0 0"/>
            <axis xyz="-1 0 0"/>
            <parent link="r_ring1"/>
            <child link="r_ring2"/>
            <limit lower="0" upper="1.7994344588061537" effort="4" velocity="4"/>
            <xacro:if value="${mimic}">
                <mimic joint="r_051ring1" multiplier="1" offset="0"/>
            </xacro:if>
        </joint>
        <link name="r_ring2">
            <visual>
                <geometry>
                    <mesh filename="mesh/r_ring2.stl"/>
                </geometry>
            </visual>
            <collision>
                <geometry>
                    <mesh filename="mesh/r_ring2.obj"/>
                </geometry>
            </collision>
            <inertial>
                <origin rpy="0 0 0" xyz="0 0 0"/>
                <mass value="0.05"/>
                <inertia ixx="1e-3" ixy="0" ixz="0" iyy="1e-3" iyz="0" izz="1e-3"/>
            </inertial>
        </link>

        <!--  pinkie  -->
        <joint name="r_053pinkie1" type="revolute">
            <origin xyz="-0.035982680943166166 0.002377759579109573 -0.09206828131946371" rpy="4.1095343980510334e-4 -0.08726646259972864 3.1154127148098776"/>
            <axis xyz="-1 0 0"/>
            <parent link="palm_base_link"/>
            <child link="r_pinkie1"/>
            <limit lower="0" upper="1.5707963267948966" effort="4" velocity="4"/>
            <xacro:if value="${mimic}">
                <mimic joint="r_051ring1" multiplier="1" offset="0"/>
            </xacro:if>
        </joint>
        <link name="r_pinkie1">
            <visual>
                <geometry>
                    <mesh filename="mesh/r_pinkie1.stl"/>
                </geometry>
            </visual>
            <collision>
                <geometry>
                    <mesh filename="mesh/r_pinkie1.obj"/>
                </geometry>
            </collision>
            <inertial>
                <origin rpy="0 0 0" xyz="0 0 0"/>
                <mass value="0.05"/>
                <inertia ixx="1e-3" ixy="0" ixz="0" iyy="1e-3" iyz="0" izz="1e-3"/>
            </inertial>
        </link>
        <joint name="r_054pinkie2" type="revolute">
            <origin xyz="0 -0.001514193309379297 -0.03499938883211873"  rpy="0 0 0"/>
            <axis xyz="-1 0 0"/>
            <parent link="r_pinkie1"/>
            <child link="r_pinkie2"/>
            <limit lower="0" upper="1.7226399717184033" effort="4" velocity="4"/>
            <xacro:if value="${mimic}">
                <mimic joint="r_053pinkie1" multiplier="1" offset="0"/>
            </xacro:if>
        </joint>
        <link name="r_pinkie2">
            <visual>
                <geometry>
                    <mesh filename="mesh/r_pinkie2.stl"/>
                </geometry>
            </visual>
            <collision>
                <geometry>
                    <mesh filename="mesh/r_pinkie2.obj"/>
                </geometry>
            </collision>
            <inertial>
                <origin rpy="0 0 0" xyz="0 0 0"/>
                <mass value="0.05"/>
                <inertia ixx="1e-3" ixy="0" ixz="0" iyy="1e-3" iyz="0" izz="1e-3"/>
            </inertial>
        </link>
    </xacro:macro>

    <xacro:macro name="ergocub_anchor">
        <!--  anchor  -->
        <link name="A_00"/>
        <link name="A_01"/>
        <link name="A_02"/>
        <link name="A_03"/>
        <link name="A_04"/>
        <link name="A_05"/>
        <link name="A_06"/>
        <link name="A_07"/>
        <link name="A_08"/>
        <link name="A_09"/>
        <link name="A_10"/>
        <link name="A_11"/>
        <link name="A_12"/>
        <link name="A_13"/>
        <link name="A_14"/>
        <link name="A_15"/>
        <link name="A_16"/>
        <link name="A_17"/>
        <link name="A_18"/>
        <link name="A_19"/>
        <link name="A_20"/>
        <link name="A_21"/>
        <!--  thumb  -->
        <joint name="joint_A_00" type="fixed">
            <child link="A_00"/>
            <parent link="r_thumb1"/>
            <origin xyz="0.03 0.01 -0.007" rpy="0 0 0"/>
        </joint>
        <joint name="joint_A_01" type="fixed">
            <child link="A_01"/>
            <parent link="r_thumb2"/>
            <origin xyz="-0.016 0.006 0" rpy="0 0 0"/>
        </joint>
        <joint name="joint_A_02" type="fixed">
            <child link="A_02"/>
            <parent link="r_thumb3"/>
            <origin xyz="0.015 -0.004 0" rpy="0 0 0"/>
        </joint>
        <joint name="joint_A_03" type="fixed">
            <child link="A_03"/>
            <parent link="r_thumb3"/>
            <origin xyz="0.041 0.001 0" rpy="0 0 0"/>
        </joint>
        <!--  index  -->
        <joint name="joint_A_04" type="fixed">
            <child link="A_04"/>
            <parent link="r_index2"/>
            <origin xyz="0 -0.005 -0.014" rpy="0 0 0"/>
        </joint>
        <joint name="joint_A_05" type="fixed">
            <child link="A_05"/>
            <parent link="r_index2"/>
            <origin xyz="0 -0.005 -0.042" rpy="0 0 0"/>
        </joint>
        <joint name="joint_A_06" type="fixed">
            <child link="A_06"/>
            <parent link="r_index3"/>
            <origin xyz="0 -0.004 -0.029" rpy="0 0 0"/>
        </joint>
        <joint name="joint_A_07" type="fixed">
            <child link="A_07"/>
            <parent link="r_index3"/>
            <origin xyz="0 -0.001 -0.045" rpy="0 0 0"/>
        </joint>
        <!--  mid  -->
        <joint name="joint_A_08" type="fixed">
            <child link="A_08"/>
            <parent link="r_middle1"/>
            <origin xyz="0 -0.005 -0.014" rpy="0 0 0"/>
        </joint>
        <joint name="joint_A_09" type="fixed">
            <child link="A_09"/>
            <parent link="r_middle1"/>
            <origin xyz="0 -0.005 -0.042" rpy="0 0 0"/>
        </joint>
        <joint name="joint_A_10" type="fixed">
            <child link="A_10"/>
            <parent link="r_middle2"/>
            <origin xyz="0 -0.004 -0.029" rpy="0 0 0"/>
        </joint>
        <joint name="joint_A_11" type="fixed">
            <child link="A_11"/>
            <parent link="r_middle2"/>
            <origin xyz="0 -0.001 -0.045" rpy="0 0 0"/>
        </joint>
        <!--  ring  -->
        <joint name="joint_A_12" type="fixed">
            <child link="A_12"/>
            <parent link="r_ring1"/>
            <origin xyz="0 -0.005 -0.014" rpy="0 0 0"/>
        </joint>
        <joint name="joint_A_13" type="fixed">
            <child link="A_13"/>
            <parent link="r_ring1"/>
            <origin xyz="0 -0.005 -0.042" rpy="0 0 0"/>
        </joint>
        <joint name="joint_A_14" type="fixed">
            <child link="A_14"/>
            <parent link="r_ring2"/>
            <origin xyz="0 -0.004 -0.029" rpy="0 0 0"/>
        </joint>
        <joint name="joint_A_15" type="fixed">
            <child link="A_15"/>
            <parent link="r_ring2"/>
            <origin xyz="0 -0.001 -0.044" rpy="0 0 0"/>
        </joint>
        <!--  pinkie  -->
        <joint name="joint_A_16" type="fixed">
            <child link="A_16"/>
            <parent link="r_pinkie1"/>
            <origin xyz="0 -0.005 -0.014" rpy="0 0 0"/>
        </joint>
        <joint name="joint_A_17" type="fixed">
            <child link="A_17"/>
            <parent link="r_pinkie1"/>
            <origin xyz="0 -0.005 -0.039" rpy="0 0 0"/>
        </joint>
        <joint name="joint_A_18" type="fixed">
            <child link="A_18"/>
            <parent link="r_pinkie2"/>
            <origin xyz="0 -0.004 -0.029" rpy="0 0 0"/>
        </joint>
        <joint name="joint_A_19" type="fixed">
            <child link="A_19"/>
            <parent link="r_pinkie2"/>
            <origin xyz="0 -0.001 -0.044" rpy="0 0 0"/>
        </joint>
        <!--  palm  -->
        <joint name="joint_A_20" type="fixed">
            <child link="A_20"/>
            <parent link="palm_base_link"/>
            <origin xyz="0.035 0.011 -0.068" rpy="0 0 0"/>
        </joint>
        <joint name="joint_A_21" type="fixed">
            <child link="A_21"/>
            <parent link="palm_base_link"/>
            <origin xyz="-0.033 0.012 -0.063" rpy="0 0 0"/>
        </joint>
    </xacro:macro>
</robot>