<!--
SPDX-FileCopyrightText: 2025 Humanoid Sensing and Perception, Istituto Italiano di Tecnologia
SPDX-License-Identifier: BSD-3-Clause
Code adapted from https://github.com/ros-industrial-attic/robotiq under BSD-2-Clause license
-->
<robot xmlns:xacro="http://www.ros.org/wiki/xacro" name="robotiq_2f85">
    <xacro:macro name="robotiq_model" params="mimic">
        <xacro:property name="yaml_file" value="../../adf/calib_eef.yaml" />
        <xacro:property name="calib_eef" value="${load_yaml(yaml_file)['robotiq_2f85']}"/>
        <!--  palm frame  -->
        <link name="eef_link">
            <inertial>
                <origin rpy="0 0 0" xyz="0 0 0"/>
                <mass value="0.0001"/>
                <inertia ixx="1e-5" ixy="0" ixz="0" iyy="1e-5" iyz="0" izz="1e-5"/>
            </inertial>
        </link>
        <joint name="r_eef_calib_joint" type="fixed">
            <parent link="eef_link"/>
            <child link="eef_calib_link"/>
            <origin xyz="${calib_eef['tx']} ${calib_eef['ty']} ${calib_eef['tz']}" 
                    rpy="${calib_eef['rx']} ${calib_eef['ry']} ${calib_eef['rz']}"/>
        </joint>
        <link name="eef_calib_link">
            <inertial>
                <origin rpy="0 0 0" xyz="0 0 0"/>
                <mass value="0.0001"/>
                <inertia ixx="1e-5" ixy="0" ixz="0" iyy="1e-5" iyz="0" izz="1e-5"/>
            </inertial>
        </link>
        <joint name="r_eef_fixed_joint" type="fixed">
            <parent link="eef_calib_link"/>
            <child link="palm_base_link"/>
            <origin xyz="-0.088 0.0 0.0" rpy="3.1416 -1.5708 0.0"/>
        </joint>
        <link name="palm_base_link">
            <visual>
                <geometry>
                    <mesh filename="mesh/base_link.stl"/>
                </geometry>
            </visual>
            <collision>
                <geometry>
                    <mesh filename="mesh/base_link.obj"/>
                </geometry>
            </collision>
            <inertial>
                <origin rpy="0 0 0" xyz="0 0 0"/>
                <mass value="0.1"/>
                <inertia ixx="1e-3" ixy="0" ixz="0" iyy="1e-3" iyz="0" izz="1e-3"/>
            </inertial>
        </link>
        <joint name="r_forearm_fixed_joint" type="fixed">
            <parent link="palm_base_link"/>
            <child link="r_forearm"/>
            <origin xyz="0 0 0" rpy="0 -1.5708 0"/>
        </joint>
		<link name="r_forearm"/>

        <!--  left finger  -->
        <joint name="r_00outer_knuckle_joint" type="revolute">
            <origin rpy="0 0 3.14159265359" xyz="0 -0.0306011 0.054904"/>
            <parent link="palm_base_link"/>
            <child link="gripper_left_outer_knuckle"/>
            <axis xyz="1 0 0"/>
            <limit effort="1000" lower="0" upper="0.82" velocity="2.0"/>
        </joint>
        <link name="gripper_left_outer_knuckle">
            <visual>
                <geometry>
                    <mesh filename="mesh/outer_knuckle.stl"/>
                </geometry>
            </visual>
            <collision>
                <geometry>
                    <mesh filename="mesh/outer_knuckle.obj"/>
                </geometry>
            </collision>
            <inertial>
                <origin rpy="0 0 0" xyz="0 0 0"/>
                <mass value="0.02"/>
                <inertia ixx="1e-3" ixy="0" ixz="0" iyy="1e-3" iyz="0" izz="1e-3"/>
            </inertial>
        </link>
        <joint name="r_01left_outer_finger_joint" type="fixed">
            <origin rpy="0 0 0" xyz="0 0.0315 -0.0041"/>
            <parent link="gripper_left_outer_knuckle"/>
            <child link="gripper_left_outer_finger"/>
            <axis xyz="1 0 0"/>
        </joint>
        <link name="gripper_left_outer_finger">
            <visual>
                <geometry>
                    <mesh filename="mesh/outer_finger.stl"/>
                </geometry>
            </visual>
            <collision>
                <geometry>
                    <mesh filename="mesh/outer_finger.obj"/>
                </geometry>
            </collision>
            <inertial>
                <origin rpy="0 0 0" xyz="0 0 0"/>
                <mass value="0.02"/>
                <inertia ixx="1e-3" ixy="0" ixz="0" iyy="1e-3" iyz="0" izz="1e-3"/>
            </inertial>
        </link>
        <joint name="r_02left_inner_finger_joint" type="revolute">
            <origin rpy="0 0 0" xyz="0 0.0061 0.0471"/>
            <parent link="gripper_left_outer_finger"/>
            <child link="gripper_left_inner_finger"/>
            <axis xyz="1 0 0"/>
            <limit effort="1000" lower="-0.82" upper="0" velocity="2.0"/>
            <xacro:if value="${mimic}">
                <mimic joint="r_00outer_knuckle_joint" multiplier="-1" offset="0"/>
            </xacro:if>
        </joint>
        <link name="gripper_left_inner_finger">
            <visual>
                <geometry>
                    <mesh filename="mesh/inner_finger.stl"/>
                </geometry>
            </visual>
            <collision>
                <geometry>
                    <mesh filename="mesh/inner_finger.obj"/>
                </geometry>
            </collision>
            <inertial>
                <origin rpy="0 0 0" xyz="0 0 0"/>
                <mass value="0.02"/>
                <inertia ixx="1e-3" ixy="0" ixz="0" iyy="1e-3" iyz="0" izz="1e-3"/>
            </inertial>
        </link>
        <joint name="r_03left_inner_finger_pad_joint0" type="fixed">
            <origin rpy="0 0 0" xyz="0 0 0"/>
            <parent link="gripper_left_inner_finger"/>
            <child link="gripper_left_inner_finger_pad0"/>
        </joint>
        <link name="gripper_left_inner_finger_pad0">
            <visual>
                <geometry>
                    <mesh filename="mesh/fingertip_f0.stl"/>
                </geometry>
            </visual>
            <collision>
                <geometry>
                    <mesh filename="mesh/fingertip_f0.stl"/>
                </geometry>
            </collision>
            <inertial>
                <origin rpy="0 0 0" xyz="0 0 0"/>
                <mass value="0.02"/>
                <inertia ixx="1e-3" ixy="0" ixz="0" iyy="1e-3" iyz="0" izz="1e-3"/>
            </inertial>
        </link>
        <joint name="r_04left_inner_finger_pad_joint1" type="fixed">
            <origin rpy="0 0 0" xyz="0 0 0"/>
            <parent link="gripper_left_inner_finger"/>
            <child link="gripper_left_inner_finger_pad1"/>
        </joint>
        <link name="gripper_left_inner_finger_pad1">
            <visual>
                <geometry>
                    <mesh filename="mesh/fingertip_f1.stl"/>
                </geometry>
            </visual>
            <collision>
                <geometry>
                    <mesh filename="mesh/fingertip_f1.stl"/>
                </geometry>
            </collision>
            <inertial>
                <origin rpy="0 0 0" xyz="0 0 0"/>
                <mass value="0.005"/>
                <inertia ixx="1e-3" ixy="0" ixz="0" iyy="1e-3" iyz="0" izz="1e-3"/>
            </inertial>
        </link>
        <joint name="r_05left_inner_knuckle_joint" type="revolute">
            <origin rpy="0 0 3.14159265359" xyz="0 -0.0127 0.06142"/>
            <parent link="palm_base_link"/>
            <child link="gripper_left_inner_knuckle"/>
            <axis xyz="1 0 0"/>
            <limit effort="1000" lower="0" upper="0.82" velocity="2.0"/>
            <xacro:if value="${mimic}">
                <mimic joint="r_00outer_knuckle_joint" multiplier="1" offset="0"/>
            </xacro:if>
        </joint>
        <link name="gripper_left_inner_knuckle">
            <visual>
                <geometry>
                    <mesh filename="mesh/inner_knuckle.stl"/>
                </geometry>
            </visual>
            <collision>
                <geometry>
                    <mesh filename="mesh/inner_knuckle.obj"/>
                </geometry>
            </collision>
            <inertial>
                <origin rpy="0 0 0" xyz="0 0 0"/>
                <mass value="0.02"/>
                <inertia ixx="1e-3" ixy="0" ixz="0" iyy="1e-3" iyz="0" izz="1e-3"/>
            </inertial>
        </link>

        <!--  right finger  -->
        <joint name="r_10right_outer_knuckle_joint" type="revolute">
            <origin rpy="0 0 0" xyz="0 0.0306011 0.054904"/>
            <parent link="palm_base_link"/>
            <child link="gripper_right_outer_knuckle"/>
            <axis xyz="1 0 0"/>
            <limit effort="1000" lower="0" upper="0.82" velocity="2.0"/>
            <xacro:if value="${mimic}">
                <mimic joint="r_00outer_knuckle_joint" multiplier="1" offset="0"/>
            </xacro:if>
        </joint>
        <link name="gripper_right_outer_knuckle">
            <visual>
                <geometry>
                    <mesh filename="mesh/outer_knuckle.stl"/>
                </geometry>
            </visual>
            <collision>
                <geometry>
                    <mesh filename="mesh/outer_knuckle.obj"/>
                </geometry>
            </collision>
            <inertial>
                <origin rpy="0 0 0" xyz="0 0 0"/>
                <mass value="0.02"/>
                <inertia ixx="1e-3" ixy="0" ixz="0" iyy="1e-3" iyz="0" izz="1e-3"/>
            </inertial>
        </link>
        <joint name="r_11right_outer_finger_joint" type="fixed">
            <origin rpy="0 0 0" xyz="0 0.0315 -0.0041"/>
            <parent link="gripper_right_outer_knuckle"/>
            <child link="gripper_right_outer_finger"/>
            <axis xyz="1 0 0"/>
        </joint>
        <link name="gripper_right_outer_finger">
            <visual>
                <geometry>
                    <mesh filename="mesh/outer_finger.stl"/>
                </geometry>
            </visual>
            <collision>
                <geometry>
                    <mesh filename="mesh/outer_finger.obj"/>
                </geometry>
            </collision>
            <inertial>
                <origin rpy="0 0 0" xyz="0 0 0"/>
                <mass value="0.02"/>
                <inertia ixx="1e-3" ixy="0" ixz="0" iyy="1e-3" iyz="0" izz="1e-3"/>
            </inertial>
        </link>
        <joint name="r_12right_inner_finger_joint" type="revolute">
            <origin rpy="0 0 0" xyz="0 0.0061 0.0471"/>
            <parent link="gripper_right_outer_finger"/>
            <child link="gripper_right_inner_finger"/>
            <axis xyz="1 0 0"/>
            <limit effort="1000" lower="-0.82" upper="0" velocity="2.0"/>
            <xacro:if value="${mimic}">
                <mimic joint="r_00outer_knuckle_joint" multiplier="-1" offset="0"/>
            </xacro:if>
        </joint>
        <link name="gripper_right_inner_finger">
            <visual>
                <geometry>
                    <mesh filename="mesh/inner_finger.stl"/>
                </geometry>
            </visual>
            <collision>
                <geometry>
                    <mesh filename="mesh/inner_finger.obj"/>
                </geometry>
            </collision>
            <inertial>
                <origin rpy="0 0 0" xyz="0 0 0"/>
                <mass value="0.02"/>
                <inertia ixx="1e-3" ixy="0" ixz="0" iyy="1e-3" iyz="0" izz="1e-3"/>
            </inertial>
        </link>
        <joint name="r_13right_inner_finger_pad_joint0" type="fixed">
            <origin rpy="0 0 0" xyz="0 0 0"/>
            <parent link="gripper_right_inner_finger"/>
            <child link="gripper_right_inner_finger_pad0"/>
        </joint>
        <link name="gripper_right_inner_finger_pad0">
            <visual>
                <geometry>
                    <mesh filename="mesh/fingertip_f0.stl"/>
                </geometry>
            </visual>
            <collision>
                <geometry>
                    <mesh filename="mesh/fingertip_f0.stl"/>
                </geometry>
            </collision>
            <inertial>
                <origin rpy="0 0 0" xyz="0 0 0"/>
                <mass value="0.005"/>
                <inertia ixx="1e-3" ixy="0" ixz="0" iyy="1e-3" iyz="0" izz="1e-3"/>
            </inertial>
        </link>
        <joint name="r_14right_inner_finger_pad_joint1" type="fixed">
            <origin rpy="0 0 0" xyz="0 0 0"/>
            <parent link="gripper_right_inner_finger"/>
            <child link="gripper_right_inner_finger_pad1"/>
        </joint>
        <link name="gripper_right_inner_finger_pad1">
            <visual>
                <geometry>
                    <mesh filename="mesh/fingertip_f1.stl"/>
                </geometry>
            </visual>
            <collision>
                <geometry>
                    <mesh filename="mesh/fingertip_f1.stl"/>
                </geometry>
            </collision>
            <inertial>
                <origin rpy="0 0 0" xyz="0 0 0"/>
                <mass value="0.005"/>
                <inertia ixx="1e-3" ixy="0" ixz="0" iyy="1e-3" iyz="0" izz="1e-3"/>
            </inertial>
        </link>
        <joint name="r_15right_inner_knuckle_joint" type="revolute">
            <origin rpy="0 0 0" xyz="0 0.0127 0.06142"/>
            <parent link="palm_base_link"/>
            <child link="gripper_right_inner_knuckle"/>
            <axis xyz="1 0 0"/>
            <limit effort="1000" lower="0" upper="0.82" velocity="2.0"/>
            <xacro:if value="${mimic}">
                <mimic joint="r_00outer_knuckle_joint" multiplier="1" offset="0"/>
            </xacro:if>
        </joint>
        <link name="gripper_right_inner_knuckle">
            <visual>
                <geometry>
                    <mesh filename="mesh/inner_knuckle.stl"/>
                </geometry>
            </visual>
            <collision>
                <geometry>
                    <mesh filename="mesh/inner_knuckle.obj"/>
                </geometry>
            </collision>
            <inertial>
                <origin rpy="0 0 0" xyz="0 0 0"/>
                <mass value="0.02"/>
                <inertia ixx="1e-3" ixy="0" ixz="0" iyy="1e-3" iyz="0" izz="1e-3"/>
            </inertial>
        </link>
    </xacro:macro>

    <xacro:macro name="robotiq_anchor">
        <!--  anchor  -->
        <link name="A_00"/>
        <link name="A_01"/>
        <link name="A_02"/>
        <link name="A_03"/>
        <link name="A_04"/>
        <link name="A_05"/>
        <link name="A_06"/>
        <link name="A_07"/>
        <link name="A_08"/>
        <link name="A_09"/>
        <link name="A_10"/>
        <link name="A_11"/>
        <link name="A_12"/>
        <link name="A_13"/>
        <link name="A_14"/>
        <link name="A_15"/>
        <link name="A_16"/>
        <link name="A_17"/>
        <link name="A_18"/>
        <link name="A_19"/>
        <link name="A_20"/>
        <link name="A_21"/>
        <!--  thumb  -->
        <joint name="joint_A_00" type="fixed">
            <child link="A_00"/>
            <parent link="gripper_left_inner_knuckle"/>
            <origin xyz="0 0.021 0.034" rpy="0 0 0"/>
        </joint>
        <joint name="joint_A_01" type="fixed">
            <child link="A_01"/>
            <parent link="gripper_left_inner_finger"/>
            <origin xyz="0 -0.024 0.01" rpy="0 0 0"/>
        </joint>
        <joint name="joint_A_02" type="fixed">
            <child link="A_02"/>
            <parent link="gripper_left_inner_finger_pad1"/>
            <origin xyz="0 -0.025 0.033" rpy="0 0 0"/>
        </joint>
        <joint name="joint_A_03" type="fixed">
            <child link="A_03"/>
            <parent link="gripper_left_inner_finger_pad1"/>
            <origin xyz="0 -0.025 0.051" rpy="0 0 0"/>
        </joint>

        <!--  index  -->
        <joint name="joint_A_04" type="fixed">
            <child link="A_04"/>
            <parent link="gripper_right_inner_knuckle"/>
            <origin xyz="0 0.021 0.034" rpy="0 0 0"/>
        </joint>
        <joint name="joint_A_05" type="fixed">
            <child link="A_05"/>
            <parent link="gripper_right_inner_finger"/>
            <origin xyz="0 -0.024 0.01" rpy="0 0 0"/>
        </joint>
        <joint name="joint_A_06" type="fixed">
            <child link="A_06"/>
            <parent link="gripper_right_inner_finger_pad1"/>
            <origin xyz="0 -0.025 0.033" rpy="0 0 0"/>
        </joint>
        <joint name="joint_A_07" type="fixed">
            <child link="A_07"/>
            <parent link="gripper_right_inner_finger_pad1"/>
            <origin xyz="0 -0.025 0.051" rpy="0 0 0"/>
        </joint>
        <!--  mid  -->
        <joint name="joint_A_08" type="fixed">
            <child link="A_08"/>
            <parent link="gripper_right_inner_knuckle"/>
            <origin xyz="0 0.021 0.034" rpy="0 0 0"/>
        </joint>
        <joint name="joint_A_09" type="fixed">
            <child link="A_09"/>
            <parent link="gripper_right_inner_finger"/>
            <origin xyz="0 -0.024 0.01" rpy="0 0 0"/>
        </joint>
        <joint name="joint_A_10" type="fixed">
            <child link="A_10"/>
            <parent link="gripper_right_inner_finger_pad1"/>
            <origin xyz="0 -0.025 0.033" rpy="0 0 0"/>
        </joint>
        <joint name="joint_A_11" type="fixed">
            <child link="A_11"/>
            <parent link="gripper_right_inner_finger_pad1"/>
            <origin xyz="0 -0.025 0.051" rpy="0 0 0"/>
        </joint>
        <!--  ring  -->
        <joint name="joint_A_12" type="fixed">
            <child link="A_12"/>
            <parent link="gripper_right_inner_knuckle"/>
            <origin xyz="0 0.021 0.034" rpy="0 0 0"/>
        </joint>
        <joint name="joint_A_13" type="fixed">
            <child link="A_13"/>
            <parent link="gripper_right_inner_finger"/>
            <origin xyz="0 -0.024 0.01" rpy="0 0 0"/>
        </joint>
        <joint name="joint_A_14" type="fixed">
            <child link="A_14"/>
            <parent link="gripper_right_inner_finger_pad1"/>
            <origin xyz="0 -0.025 0.033" rpy="0 0 0"/>
        </joint>
        <joint name="joint_A_15" type="fixed">
            <child link="A_15"/>
            <parent link="gripper_right_inner_finger_pad1"/>
            <origin xyz="0 -0.025 0.051" rpy="0 0 0"/>
        </joint>
        <!--  pink  -->
        <joint name="joint_A_16" type="fixed">
            <child link="A_16"/>
            <parent link="gripper_right_inner_knuckle"/>
            <origin xyz="0 0.021 0.034" rpy="0 0 0"/>
        </joint>
        <joint name="joint_A_17" type="fixed">
            <child link="A_17"/>
            <parent link="gripper_right_inner_finger"/>
            <origin xyz="0 -0.024 0.01" rpy="0 0 0"/>
        </joint>
        <joint name="joint_A_18" type="fixed">
            <child link="A_18"/>
            <parent link="gripper_right_inner_finger_pad1"/>
            <origin xyz="0 -0.025 0.033" rpy="0 0 0"/>
        </joint>
        <joint name="joint_A_19" type="fixed">
            <child link="A_19"/>
            <parent link="gripper_right_inner_finger_pad1"/>
            <origin xyz="0 -0.025 0.051" rpy="0 0 0"/>
        </joint>
        <!--  palm  -->
        <joint name="joint_A_20" type="fixed">
            <child link="A_20"/>
            <parent link="palm_base_link"/>
            <origin xyz="0.01 0 0.088" rpy="0 0 0"/>
        </joint>
        <joint name="joint_A_21" type="fixed">
            <child link="A_21"/>
            <parent link="palm_base_link"/>
            <origin xyz="-0.01 0 0.088" rpy="0 0 0"/>
        </joint>
    </xacro:macro>
</robot>